<?xml version="1.0" encoding="utf-8"?>
<!-- This URDF was automatically created by SolidWorks to URDF Exporter! Originally created by Stephen Brawner (brawner@gmail.com) 
     Commit Version: 1.6.0-1-g15f4949  Build Version: 1.6.7594.29634
     For more information, please see http://wiki.ros.org/sw_urdf_exporter -->
<robot
  name="chimuelo_description">
  <link name="base_footprint">
  </link>
  <joint name="base_joint"    type="fixed">
    <origin xyz="0 0 0.22579" rpy="0 -0.150640 0" />
    <parent link="base_footprint" />
    <child link="base_link" />
  </joint>

  <link
    name="base_link">
    <inertial>
      <origin
        xyz="-0.019376 0.0012573 0.047484"
        rpy="0 0 0" />
      <mass
        value="9.3362" />
      <inertia
        ixx="0.10996"
        ixy="-0.00014648"
        ixz="0.015965"
        iyy="0.1362"
        iyz="0.00018862"
        izz="0.18143" />
    </inertial>
    <visual>
      <origin
        xyz="0 0 0"
        rpy="0 0 0" />
      <geometry>
        <mesh
          filename="package://chimuelo_description/meshes/base_link.STL" />
      </geometry>
      <material
        name="">
        <color
          rgba="0.69412 0.098039 0.098039 1" />
      </material>
    </visual>
    <collision>
      <origin
        xyz="0 0 0.09255"
        rpy="0 0.150640 0" />
      <geometry>
        <!--mesh
          filename="package://chimuelo_description/meshes/base_link.STL" /-->
        <box size="0.4806 0.316 0.35323" />
      </geometry>
    </collision>
  </link>
  <link
    name="front_right_wheel">
    <inertial>
      <origin
        xyz="-0.030145 7.2299E-06 -7.774E-07"
        rpy="0 0 0" />
      <mass
        value="0.95802" />
      <inertia
        ixx="0.0027027"
        ixy="3.8106E-07"
        ixz="-4.0985E-08"
        iyy="0.0015854"
        iyz="-3.6463E-09"
        izz="0.0015854" />
    </inertial>
    <visual>
      <origin
        xyz="0 0 0"
        rpy="0 0 3.1416" />
      <geometry>
        <mesh
          filename="package://chimuelo_description/meshes/front_right_wheel.STL" />
      </geometry>
      <material
        name="">
        <color
          rgba="0.79216 0.81961 0.93333 1" />
      </material>
    </visual>
    <collision>
      <origin
        xyz="0.027 0 0"
        rpy="0 1.5708 0" />
      <geometry>
        <!--mesh
          filename="package://chimuelo_description/meshes/front_right_wheel.STL" /-->
        <cylinder length="0.054" radius="0.079375" />
      </geometry>
    </collision>
  </link>
  <joint
    name="front_right_joint"
    type="continuous">
    <origin
      xyz="0.15956 -0.22452 -0.14324"
      rpy="0.150640 0 1.5708" />
    <parent
      link="base_link" />
    <child
      link="front_right_wheel" />
    <axis
      xyz="1 0 0" />
  </joint>
  <link
    name="front_left_wheel">
    <inertial>
      <origin
        xyz="0.080855 -3.7512E-06 6.2293E-06"
        rpy="0 0 0" />
      <mass
        value="0.95802" />
      <inertia
        ixx="0.0027027"
        ixy="-1.9771E-07"
        ixz="3.2833E-07"
        iyy="0.0015854"
        iyz="-1.5204E-08"
        izz="0.0015854" />
    </inertial>
    <visual>
      <origin
        xyz="0 0 0"
        rpy="0 0 0" />
      <geometry>
        <mesh
          filename="package://chimuelo_description/meshes/front_left_wheel.STL" />
      </geometry>
      <material
        name="">
        <color
          rgba="0.79216 0.81961 0.93333 1" />
      </material>
    </visual>
    <collision>
      <origin
        xyz="0.081 0 0"
        rpy="0 1.5708 0" />
      <geometry>
        <!--mesh
          filename="package://chimuelo_description/meshes/front_left_wheel.STL" /-->
        <cylinder length="0.054" radius="0.079375" />
      </geometry>
    </collision>
  </link>
  <joint
    name="front_left_joint"
    type="continuous">
    <origin
      xyz="0.15956 0.11368 -0.14324"
      rpy="0.150640 0 1.5708" />
    <parent
      link="base_link" />
    <child
      link="front_left_wheel" />
    <axis
      xyz="1 0 0" />
  </joint>
  <link
    name="rear_right_link">
    <inertial>
      <origin
        xyz="-0.013975 0.054321 9.9024E-05"
        rpy="0 0 0" />
      <mass
        value="0.053734" />
      <inertia
        ixx="2.524E-05"
        ixy="-1.6585E-06"
        ixz="9.9779E-08"
        iyy="2.9055E-05"
        iyz="2.0355E-07"
        izz="2.0458E-05" />
    </inertial>
    <visual>
      <origin
        xyz="0 0 0"
        rpy="0 0 0" />
      <geometry>
        <mesh
          filename="package://chimuelo_description/meshes/rear_right_link.STL" />
      </geometry>
      <material
        name="">
        <color
          rgba="0.25098 0.25098 0.25098 1" />
      </material>
    </visual>
    <collision>
      <origin
        xyz="0 0.07459 0"
        rpy="1.5708 0 0" />
      <geometry>
        <!--mesh
          filename="package://chimuelo_description/meshes/rear_right_link.STL" /-->
        <box size="0.107 0.086 0.025" />
      </geometry>
    </collision>
  </link>
  <joint
    name="rear_right_joint1"
    type="continuous">
    <origin
      xyz="-0.12756 -0.076921 -0.14918"
      rpy="1.5688 0.13961 -0.014686" />
    <parent
      link="base_link" />
    <child
      link="rear_right_link" />
    <axis
      xyz="0 1 0" />
  </joint>
  <link
    name="rear_right_wheel">
    <inertial>
      <origin
        xyz="0.0014035 7.5454E-12 1.17E-06"
        rpy="0 0 0" />
      <mass
        value="0.2056" />
      <inertia
        ixx="0.00020145"
        ixy="-4.2403E-14"
        ixz="-5.6953E-14"
        iyy="0.00011972"
        iyz="5.3531E-16"
        izz="0.00011972" />
    </inertial>
    <visual>
      <origin
        xyz="0 0 0"
        rpy="0 0 0" />
      <geometry>
        <mesh
          filename="package://chimuelo_description/meshes/rear_right_wheel.STL" />
      </geometry>
      <material
        name="">
        <color
          rgba="0.79216 0.81961 0.93333 1" />
      </material>
    </visual>
    <collision>
      <origin
        xyz="0 0 0"
        rpy="0 -1.5708 0" />
      <geometry>
        <!--mesh
          filename="package://chimuelo_description/meshes/rear_right_wheel.STL" /-->
        <cylinder length="0.032" radius="0.045" />
      </geometry>
    </collision>
  </link>
  <joint
    name="rear_right_joint2"
    type="continuous">
    <origin
      xyz="-0.03659 0.014924 -0.0015141"
      rpy="2.894 -1.5708 0" />
    <parent
      link="rear_right_link" />
    <child
      link="rear_right_wheel" />
    <axis
      xyz="1 0 0" />
  </joint>
  <link
    name="rear_left_link">
    <inertial>
      <origin
        xyz="-0.013975 0.054321 9.9024E-05"
        rpy="0 0 0" />
      <mass
        value="0.053734" />
      <inertia
        ixx="2.524E-05"
        ixy="-1.6585E-06"
        ixz="9.9779E-08"
        iyy="2.9055E-05"
        iyz="2.0355E-07"
        izz="2.0458E-05" />
    </inertial>
    <visual>
      <origin
        xyz="0 0 0"
        rpy="0 0 0" />
      <geometry>
        <mesh
          filename="package://chimuelo_description/meshes/rear_left_link.STL" />
      </geometry>
      <material
        name="">
        <color
          rgba="0.25098 0.25098 0.25098 1" />
      </material>
    </visual>
    <collision>
      <origin
        xyz="0 0.07459 0"
        rpy="1.5708 0 0" />
      <geometry>
        <!--mesh
          filename="package://chimuelo_description/meshes/rear_left_link.STL" /-->
        <box size="0.107 0.086 0.025" />
      </geometry>
    </collision>
  </link>
  <joint
    name="rear_left_joint1"
    type="continuous">
    <origin
      xyz="-0.12756 0.077079 -0.14918"
      rpy="1.5688 0.13961 -0.014686" />
    <parent
      link="base_link" />
    <child
      link="rear_left_link" />
    <axis
      xyz="0 1 0" />
  </joint>
  <link
    name="rear_left_wheel">
    <inertial>
      <origin
        xyz="0.0014035 7.5453E-12 1.17E-06"
        rpy="0 0 0" />
      <mass
        value="0.2056" />
      <inertia
        ixx="0.00020145"
        ixy="-4.2403E-14"
        ixz="-5.6953E-14"
        iyy="0.00011972"
        iyz="5.3532E-16"
        izz="0.00011972" />
    </inertial>
    <visual>
      <origin
        xyz="0 0 0"
        rpy="0 0 0" />
      <geometry>
        <mesh
          filename="package://chimuelo_description/meshes/rear_left_wheel.STL" />
      </geometry>
      <material
        name="">
        <color
          rgba="0.79216 0.81961 0.93333 1" />
      </material>
    </visual>
    <collision>
      <origin
        xyz="0 0 0"
        rpy="0 -1.5708 0" />
      <geometry>
        <!--mesh
          filename="package://chimuelo_description/meshes/rear_left_wheel.STL" /-->
        <cylinder length="0.032" radius="0.045" />
      </geometry>
    </collision>
  </link>
  <joint
    name="rear_left_joint2"
    type="continuous">
    <origin
      xyz="-0.03659 0.014924 -0.0015141"
      rpy="2.894 -1.5708 0" />
    <parent
      link="rear_left_link" />
    <child
      link="rear_left_wheel" />
    <axis
      xyz="1 0 0" />
  </joint>
  <!-- Adding front camera -->
  	<link name="camera_link">
	    <collision>
		      <origin xyz="0 0 0" rpy="0 0 0"/>
		      <geometry>
			    <box size="0.05 0.05 0.05"/>
		      </geometry>
	    </collision>
	    <visual>
		      <origin xyz="0 0 0" rpy="0 0 0"/>
		      <geometry>
			    <box size="0.05 0.05 0.05"/>
		      </geometry>
	    </visual>
	    <inertial>
		      <mass value="1e-5" />
		      <origin xyz="0 0 0" rpy="0 0 0"/>
		      <inertia ixx="1e-6" ixy="0" ixz="0" iyy="1e-6" iyz="0" izz="1e-6" />
	    </inertial>
	</link>

	<joint name="camera_joint" type="fixed">
	    <axis xyz="0 0 1" />
	    <origin xyz="0 0 0.6" rpy="0 0 0"/>
	    <parent link="base_footprint"/>
	    <child link="camera_link"/>
	</joint>
	
  	<gazebo>
		<plugin name="differential_drive_controller" filename="libgazebo_ros_diff_drive.so">

			<commandTopic>/cmd_vel</commandTopic>
			<odometryTopic>odom</odometryTopic>
			<odometryFrame>odom</odometryFrame>
			<odometrySource>world</odometrySource>
			<publishOdomTF>true</publishOdomTF>
			<robotBaseFrame>base_footprint</robotBaseFrame>
			<publishWheelTF>false</publishWheelTF>
			<publishTf>true</publishTf>
			<publishWheelJointState>true</publishWheelJointState>
			<legacyMode>false</legacyMode>
			<updateRate>30</updateRate>
			<leftJoint>front_left_joint</leftJoint>
			<rightJoint>front_right_joint</rightJoint>
			<wheelSeparation>0.33820</wheelSeparation>
			<wheelDiameter>0.15875</wheelDiameter>
			<wheelAcceleration>1</wheelAcceleration>
			<wheelTorque>10</wheelTorque>
			<rosDebugLevel>na</rosDebugLevel>

		</plugin>
	</gazebo>
	<!-- Camera plugin -->
  <gazebo reference="camera_link">
    <sensor type="camera" name="camera1">
    <visualize>true</visualize>
      <update_rate>30.0</update_rate>
      <camera name="head">
        <horizontal_fov>1.3962634</horizontal_fov>
        <image>
          <width>800</width>
          <height>800</height>
          <format>R8G8B8</format>
        </image>
        <clip>
          <near>0.02</near>
          <far>300</far>
        </clip>
        <noise>
          <type>gaussian</type>
          <!-- Noise is sampled independently per pixel on each frame.
               That pixel's noise value is added to each of its color
               channels, which at that point lie in the range [0,1]. -->
          <mean>0.0</mean>
          <stddev>0.007</stddev>
        </noise>
      </camera>
      <plugin name="camera_controller" filename="libgazebo_ros_camera.so">
        <alwaysOn>true</alwaysOn>
        <updateRate>0.0</updateRate>
        <cameraName>chimuelo/camera1</cameraName>
        <imageTopicName>image_raw</imageTopicName>
        <cameraInfoTopicName>camera_info</cameraInfoTopicName>
        <frameName>camera_link</frameName>
        <hackBaseline>0.07</hackBaseline>
        <distortionK1>0.0</distortionK1>
        <distortionK2>0.0</distortionK2>
        <distortionK3>0.0</distortionK3>
        <distortionT1>0.0</distortionT1>
        <distortionT2>0.0</distortionT2>
      </plugin>
    </sensor>
  </gazebo>
  
  <!-- LiDar plugin -->
  <gazebo reference="camera_link">
    <sensor type="ray" name="LiDar">
    <pose>0 0 0 0 0 0</pose>
    <visualize>true</visualize>
      <update_rate>30.0</update_rate>
      <ray>
        <scan>
          <horizontal>
            <samples>32</samples>
            <resolution>1</resolution>
            <min_angle>-0.53529248</min_angle>
            <max_angle>0.18622663</max_angle>
          </horizontal>
          <vertical>
            <samples>16</samples>
            <resolution>1</resolution>
            <min_angle>-0.53529248</min_angle>
            <max_angle>0.18622663</max_angle>
          </vertical>
        </scan>
        <range>
          <min>0.10</min>
          <max>30.0</max>
          <resolution>0.02</resolution>
        </range>
        <noise>
          <type>gaussian</type>
          <!-- Noise parameters based on published spec for Hokuyo laser
               achieving "+-30mm" accuracy at range < 10m.  A mean of 0.0m and
               stddev of 0.01m will put 99.7% of samples within 0.03m of the true
               reading. -->
          <mean>0.0</mean>
          <stddev>0.01</stddev>
        </noise>
      </ray>
      <plugin name="gazebo_ros_head_hokuyo_controller" filename="libgazebo_ros_block_laser.so">
        <topicName>/chimuelo/laser/scan</topicName>
        <frameName>camera_link</frameName>
      </plugin>
    </sensor>
  </gazebo>
  
</robot>
